<sdf version='1.6'>
    <world name='default'>
        <light name='sun' type='directional'>
            <cast_shadows>1</cast_shadows>
            <pose frame=''>0 0 10 0 -0 0</pose>
            <diffuse>0.8 0.8 0.8 1</diffuse>
            <specular>0.1 0.1 0.1 1</specular>
            <attenuation>
                <range>1000</range>
                <constant>0.9</constant>
                <linear>0.01</linear>
                <quadratic>0.001</quadratic>
            </attenuation>
            <direction>-0.5 0.5 -1</direction>
        </light>
        <gravity>0 0 -9.8</gravity>
        <magnetic_field>6e-06 2.3e-05 -4.2e-05</magnetic_field>
        <atmosphere type='adiabatic'/>
        <physics name='default_physics' default='0' type='ode'>
            <max_step_size>0.001</max_step_size>
            <real_time_factor>1</real_time_factor>
            <real_time_update_rate>1000</real_time_update_rate>
        </physics>
        <scene>
            <ambient>0.4 0.4 0.4 1</ambient>
            <background>0.7 0.7 0.7 1</background>
            <shadows>1</shadows>
        </scene>
        <gui fullscreen='0'>
            <camera name='user_camera'>
                <pose frame=''>4.6981 3.66094 17.2414 -0 1.4458 3.1282</pose>
                <view_controller>orbit</view_controller>
                <projection_type>perspective</projection_type>
            </camera>
        </gui>
        <spherical_coordinates>
            <surface_model>EARTH_WGS84</surface_model>
            <latitude_deg>0</latitude_deg>
            <longitude_deg>0</longitude_deg>
            <elevation>0</elevation>
            <heading_deg>0</heading_deg>
        </spherical_coordinates>
        <state world_name='default'>
            <sim_time>298 937000000</sim_time>
            <real_time>0 0</real_time>
            <wall_time>1480503833 854480719</wall_time>
            <iterations>2</iterations>
            <model name='ground_plane'>
                <pose frame=''>0 0 0 0 -0 0</pose>
                <scale>1 1 1</scale>
            </model>
            <model name='square_map'>
                <pose frame=''>-0 0 0 0 -0 0</pose>
            </model>
            <model name='robot_1'>
                <pose frame=''>-3 -3 0 0 0 1.571</pose>
                <scale>1 1 1</scale>
            </model>
            <model name='robot_2'>
                <pose frame=''>-3 3 0 0 0 0</pose>
                <scale>1 1 1</scale>
            </model>
            <model name='robot_3'>
                <pose frame=''>3 -3 0 0 0 3.142</pose>
                <scale>1 1 1</scale>
            </model>
            <model name='robot_4'>
                <pose frame=''>3 3 0 0 0 -1.571</pose>
                <scale>1 1 1</scale>
            </model>
            <light name='sun'>
                <pose frame=''>0 0 10 0 -0 0</pose>
            </light>
        </state>

        <model name='ground_plane'>
            <static>1</static>
            <link name='link'>
                <collision name='collision'>
                    <geometry>
                        <plane>
                            <normal>0 0 1</normal>
                            <size>100 100</size>
                        </plane>
                    </geometry>
                    <surface>
                        <friction>
                            <ode>
                                <mu>100</mu>
                                <mu2>50</mu2>
                            </ode>
                            <torsional>
                                <ode/>
                            </torsional>
                        </friction>
                        <contact>
                            <ode/>
                        </contact>
                        <bounce/>
                    </surface>
                    <max_contacts>10</max_contacts>
                </collision>
                <visual name='visual'>
                    <cast_shadows>0</cast_shadows>
                    <geometry>
                        <plane>
                            <normal>0 0 1</normal>
                            <size>110 110</size>
                        </plane>
                    </geometry>
                    <material>
                        <script>
                            <uri>file://media/materials/scripts/gazebo.material</uri>
                            <name>Gazebo/Grey</name>
                        </script>
                    </material>
                </visual>
                <self_collide>0</self_collide>
                <kinematic>0</kinematic>
            </link>
        </model>

        <model name='square_map'>
            <link name='link'>
                <pose frame=''>-0 0 0 0 -0 0</pose>
                <inertial>
                    <mass>1</mass>
                    <inertia>
                        <ixx>0.166667</ixx>
                        <ixy>0</ixy>
                        <ixz>0</ixz>
                        <iyy>0.166667</iyy>
                        <iyz>0</iyz>
                        <izz>0.166667</izz>
                    </inertia>
                    <pose frame=''>0 0 0 0 -0 0</pose>
                </inertial>
                <gravity>1</gravity>
                <self_collide>0</self_collide>
                <kinematic>0</kinematic>
                <visual name='visual'>
                    <pose frame=''>0 0 0 0 -0 0</pose>
                    <geometry>
                        <polyline>
                            <height>0.5</height>
                            <point>-4.5 4.5</point>
                            <point>4.5 4.5</point>
                            <point>4.5 -4.5</point>
                            <point>-4.5 -4.5</point>
                            <point>-4.5 -5</point>
                            <point>5 -5</point>
                            <point>5 5</point>
                            <point>-5 5</point>
                            <point>-5 -5</point>
                            <point>-4.50446 -4.99107</point>
                            <point>-4.5 4.5</point>
                        </polyline>
                    </geometry>
                    <material>
                        <lighting>1</lighting>
                        <script>
                            <uri>file://media/materials/scripts/gazebo.material</uri>
                            <name>Gazebo/Grey</name>
                        </script>
                        <ambient>0.6 0.3 0 1</ambient>
                        <diffuse>0.7 0.7 0.7 1</diffuse>
                        <specular>0.01 0.01 0.01 1</specular>
                        <emissive>0 0 0 1</emissive>
                        <shader type='vertex'>
                            <normal_map>__default__</normal_map>
                        </shader>
                    </material>
                    <transparency>0</transparency>
                    <cast_shadows>1</cast_shadows>
                </visual>
                <collision name='collision'>
                    <laser_retro>0</laser_retro>
                    <max_contacts>10</max_contacts>
                    <pose frame=''>0 0 0 0 -0 0</pose>
                    <geometry>
                        <polyline>
                            <height>0.5</height>
                            <point>-4.5 4.5</point>
                            <point>4.5 4.5</point>
                            <point>4.5 -4.5</point>
                            <point>-4.5 -4.5</point>
                            <point>-4.5 -5</point>
                            <point>5 -5</point>
                            <point>5 5</point>
                            <point>-5 5</point>
                            <point>-5 -5</point>
                            <point>-4.50446 -4.99107</point>
                            <point>-4.5 4.5</point>
                        </polyline>
                    </geometry>
                    <surface>
                        <friction>
                            <ode>
                                <mu>1</mu>
                                <mu2>1</mu2>
                                <fdir1>0 0 0</fdir1>
                                <slip1>0</slip1>
                                <slip2>0</slip2>
                            </ode>
                            <torsional>
                                <coefficient>1</coefficient>
                                <patch_radius>0</patch_radius>
                                <surface_radius>0</surface_radius>
                                <use_patch_radius>1</use_patch_radius>
                                <ode>
                                    <slip>0</slip>
                                </ode>
                            </torsional>
                        </friction>
                        <bounce>
                            <restitution_coefficient>0</restitution_coefficient>
                            <threshold>1e+06</threshold>
                        </bounce>
                        <contact>
                            <collide_without_contact>0</collide_without_contact>
                            <collide_without_contact_bitmask>1</collide_without_contact_bitmask>
                            <collide_bitmask>1</collide_bitmask>
                            <ode>
                                <soft_cfm>0</soft_cfm>
                                <soft_erp>0.2</soft_erp>
                                <kp>1e+13</kp>
                                <kd>1</kd>
                                <max_vel>0.01</max_vel>
                                <min_depth>0</min_depth>
                            </ode>
                            <bullet>
                                <split_impulse>1</split_impulse>
                                <split_impulse_penetration_threshold>-0.01</split_impulse_penetration_threshold>
                                <soft_cfm>0</soft_cfm>
                                <soft_erp>0.2</soft_erp>
                                <kp>1e+13</kp>
                                <kd>1</kd>
                            </bullet>
                        </contact>
                    </surface>
                </collision>
            </link>
            <static>0</static>
            <allow_auto_disable>1</allow_auto_disable>
        </model>

        <model name='robot_2'>
            <pose frame=''>1 1 0 0 0 0</pose>
            <link name='chassis'>
                <pose frame=''>0 0 0.16 0 -0 0</pose>
                <inertial>
                    <mass>5.67</mass>
                    <inertia>
                        <ixx>0.07</ixx>
                        <iyy>0.08</iyy>
                        <izz>0.1</izz>
                        <ixy>0</ixy>
                        <ixz>0</ixz>
                        <iyz>0</iyz>
                    </inertia>
                </inertial>
                <collision name='collision'>
                    <geometry>
                        <box>
                            <size>0.445 0.277 0.17</size>
                        </box>
                    </geometry>
                    <max_contacts>10</max_contacts>
                    <surface>
                        <contact>
                            <ode/>
                        </contact>
                        <bounce/>
                        <friction>
                            <torsional>
                                <ode/>
                            </torsional>
                            <ode/>
                        </friction>
                    </surface>
                </collision>
                <collision name='castor_collision'>
                    <pose frame=''>-0.2 0 -0.12 0 -0 0</pose>
                    <geometry>
                        <sphere>
                            <radius>0.04</radius>
                        </sphere>
                    </geometry>
                    <surface>
                        <friction>
                            <ode>
                                <mu>0</mu>
                                <mu2>0</mu2>
                                <slip1>1</slip1>
                                <slip2>1</slip2>
                            </ode>
                            <torsional>
                                <ode/>
                            </torsional>
                        </friction>
                        <contact>
                            <ode/>
                        </contact>
                        <bounce/>
                    </surface>
                    <max_contacts>10</max_contacts>
                </collision>
                <visual name='visual'>
                    <pose frame=''>0 0 0.04 0 -0 0</pose>
                    <geometry>
                        <mesh>
                            <uri>model://pioneer2dx/meshes/chassis.dae</uri>
                            <scale>1 1 1</scale>
                        </mesh>
                    </geometry>
                </visual>
                <visual name='castor_visual'>
                    <pose frame=''>-0.2 0 -0.12 0 -0 0</pose>
                    <geometry>
                        <sphere>
                            <radius>0.04</radius>
                        </sphere>
                    </geometry>
                    <material>
                        <script>
                            <uri>file://media/materials/scripts/gazebo.material</uri>
                            <name>Gazebo/FlatBlack</name>
                        </script>
                    </material>
                </visual>
                <self_collide>0</self_collide>
                <kinematic>0</kinematic>
            </link>
            <link name='right_wheel'>
                <pose frame=''>0.1 -0.17 0.11 -0 1.5707 1.5707</pose>
                <inertial>
                    <mass>1.5</mass>
                    <inertia>
                        <ixx>0.0051</ixx>
                        <iyy>0.0051</iyy>
                        <izz>0.009</izz>
                        <ixy>0</ixy>
                        <ixz>0</ixz>
                        <iyz>0</iyz>
                    </inertia>
                </inertial>
                <collision name='collision'>
                    <geometry>
                        <cylinder>
                            <radius>0.11</radius>
                            <length>0.05</length>
                        </cylinder>
                    </geometry>
                    <surface>
                        <friction>
                            <ode>
                                <mu>100000</mu>
                                <mu2>100000</mu2>
                                <slip1>0</slip1>
                                <slip2>0</slip2>
                            </ode>
                            <torsional>
                                <ode/>
                            </torsional>
                        </friction>
                        <contact>
                            <ode/>
                        </contact>
                        <bounce/>
                    </surface>
                    <max_contacts>10</max_contacts>
                </collision>
                <visual name='visual'>
                    <geometry>
                        <cylinder>
                            <radius>0.11</radius>
                            <length>0.05</length>
                        </cylinder>
                    </geometry>
                    <material>
                        <script>
                            <uri>file://media/materials/scripts/gazebo.material</uri>
                            <name>Gazebo/FlatBlack</name>
                        </script>
                    </material>
                </visual>
                <self_collide>0</self_collide>
                <kinematic>0</kinematic>
            </link>
            <link name='left_wheel'>
                <pose frame=''>0.1 0.17 0.11 -0 1.5707 1.5707</pose>
                <inertial>
                    <mass>1.5</mass>
                    <inertia>
                        <ixx>0.0051</ixx>
                        <iyy>0.0051</iyy>
                        <izz>0.009</izz>
                        <ixy>0</ixy>
                        <ixz>0</ixz>
                        <iyz>0</iyz>
                    </inertia>
                </inertial>
                <collision name='collision'>
                    <geometry>
                        <cylinder>
                            <radius>0.11</radius>
                            <length>0.05</length>
                        </cylinder>
                    </geometry>
                    <surface>
                        <friction>
                            <ode>
                                <mu>100000</mu>
                                <mu2>100000</mu2>
                                <slip1>0</slip1>
                                <slip2>0</slip2>
                            </ode>
                            <torsional>
                                <ode/>
                            </torsional>
                        </friction>
                        <contact>
                            <ode/>
                        </contact>
                        <bounce/>
                    </surface>
                    <max_contacts>10</max_contacts>
                </collision>
                <visual name='visual'>
                    <geometry>
                        <cylinder>
                            <radius>0.11</radius>
                            <length>0.05</length>
                        </cylinder>
                    </geometry>
                    <material>
                        <script>
                            <uri>file://media/materials/scripts/gazebo.material</uri>
                            <name>Gazebo/FlatBlack</name>
                        </script>
                    </material>
                </visual>
                <self_collide>0</self_collide>
                <kinematic>0</kinematic>
            </link>
            <joint name='left_wheel_hinge' type='revolute'>
                <pose frame=''>0 0 -0.03 0 -0 0</pose>
                <child>left_wheel</child>
                <parent>chassis</parent>
                <axis>
                    <xyz>0 1 0</xyz>
                    <use_parent_model_frame>1</use_parent_model_frame>
                    <limit>
                        <lower>-1e+16</lower>
                        <upper>1e+16</upper>
                    </limit>
                    <dynamics>
                        <spring_reference>0</spring_reference>
                        <spring_stiffness>0</spring_stiffness>
                    </dynamics>
                </axis>
            </joint>
            <joint name='right_wheel_hinge' type='revolute'>
                <pose frame=''>0 0 0.03 0 -0 0</pose>
                <child>right_wheel</child>
                <parent>chassis</parent>
                <axis>
                    <xyz>0 1 0</xyz>
                    <use_parent_model_frame>1</use_parent_model_frame>
                    <limit>
                        <lower>-1e+16</lower>
                        <upper>1e+16</upper>
                    </limit>
                    <dynamics>
                        <spring_reference>0</spring_reference>
                        <spring_stiffness>0</spring_stiffness>
                    </dynamics>
                </axis>
            </joint>

            <plugin name='differential_drive_controller' filename='librobot_ros_diff_drive.so'>
                <alwaysOn>true</alwaysOn>
                <legacyMode>true</legacyMode>
                <updateRate>40</updateRate>
                <leftJoint>left_wheel_hinge</leftJoint>
                <rightJoint>right_wheel_hinge</rightJoint>
                <wheelSeparation>0.66</wheelSeparation>
                <wheelDiameter>0.26</wheelDiameter>
                <torque>5</torque>
                <commandTopic>/robot_2/cmd_vel</commandTopic>
                <odometryTopic>/robot_2/odom</odometryTopic>
                <odometryFrame>/robot_2/chassis</odometryFrame>
                <robotBaseFrame>/robot_2/odom</robotBaseFrame>
                <publishWheelTF>true</publishWheelTF>
                <publishWheelJointState>true</publishWheelJointState>
            </plugin>
        </model>
        <model name='robot_3'>
            <pose frame=''>2 2 0 0 0 0</pose>
            <link name='chassis'>
                <pose frame=''>0 0 0.16 0 -0 0</pose>
                <inertial>
                    <mass>5.67</mass>
                    <inertia>
                        <ixx>0.07</ixx>
                        <iyy>0.08</iyy>
                        <izz>0.1</izz>
                        <ixy>0</ixy>
                        <ixz>0</ixz>
                        <iyz>0</iyz>
                    </inertia>
                </inertial>
                <collision name='collision'>
                    <geometry>
                        <box>
                            <size>0.445 0.277 0.17</size>
                        </box>
                    </geometry>
                    <max_contacts>10</max_contacts>
                    <surface>
                        <contact>
                            <ode/>
                        </contact>
                        <bounce/>
                        <friction>
                            <torsional>
                                <ode/>
                            </torsional>
                            <ode/>
                        </friction>
                    </surface>
                </collision>
                <collision name='castor_collision'>
                    <pose frame=''>-0.2 0 -0.12 0 -0 0</pose>
                    <geometry>
                        <sphere>
                            <radius>0.04</radius>
                        </sphere>
                    </geometry>
                    <surface>
                        <friction>
                            <ode>
                                <mu>0</mu>
                                <mu2>0</mu2>
                                <slip1>1</slip1>
                                <slip2>1</slip2>
                            </ode>
                            <torsional>
                                <ode/>
                            </torsional>
                        </friction>
                        <contact>
                            <ode/>
                        </contact>
                        <bounce/>
                    </surface>
                    <max_contacts>10</max_contacts>
                </collision>
                <visual name='visual'>
                    <pose frame=''>0 0 0.04 0 -0 0</pose>
                    <geometry>
                        <mesh>
                            <uri>model://pioneer2dx/meshes/chassis.dae</uri>
                            <scale>1 1 1</scale>
                        </mesh>
                    </geometry>
                </visual>
                <visual name='castor_visual'>
                    <pose frame=''>-0.2 0 -0.12 0 -0 0</pose>
                    <geometry>
                        <sphere>
                            <radius>0.04</radius>
                        </sphere>
                    </geometry>
                    <material>
                        <script>
                            <uri>file://media/materials/scripts/gazebo.material</uri>
                            <name>Gazebo/FlatBlack</name>
                        </script>
                    </material>
                </visual>
                <self_collide>0</self_collide>
                <kinematic>0</kinematic>
            </link>
            <link name='right_wheel'>
                <pose frame=''>0.1 -0.17 0.11 -0 1.5707 1.5707</pose>
                <inertial>
                    <mass>1.5</mass>
                    <inertia>
                        <ixx>0.0051</ixx>
                        <iyy>0.0051</iyy>
                        <izz>0.009</izz>
                        <ixy>0</ixy>
                        <ixz>0</ixz>
                        <iyz>0</iyz>
                    </inertia>
                </inertial>
                <collision name='collision'>
                    <geometry>
                        <cylinder>
                            <radius>0.11</radius>
                            <length>0.05</length>
                        </cylinder>
                    </geometry>
                    <surface>
                        <friction>
                            <ode>
                                <mu>100000</mu>
                                <mu2>100000</mu2>
                                <slip1>0</slip1>
                                <slip2>0</slip2>
                            </ode>
                            <torsional>
                                <ode/>
                            </torsional>
                        </friction>
                        <contact>
                            <ode/>
                        </contact>
                        <bounce/>
                    </surface>
                    <max_contacts>10</max_contacts>
                </collision>
                <visual name='visual'>
                    <geometry>
                        <cylinder>
                            <radius>0.11</radius>
                            <length>0.05</length>
                        </cylinder>
                    </geometry>
                    <material>
                        <script>
                            <uri>file://media/materials/scripts/gazebo.material</uri>
                            <name>Gazebo/FlatBlack</name>
                        </script>
                    </material>
                </visual>
                <self_collide>0</self_collide>
                <kinematic>0</kinematic>
            </link>
            <link name='left_wheel'>
                <pose frame=''>0.1 0.17 0.11 -0 1.5707 1.5707</pose>
                <inertial>
                    <mass>1.5</mass>
                    <inertia>
                        <ixx>0.0051</ixx>
                        <iyy>0.0051</iyy>
                        <izz>0.009</izz>
                        <ixy>0</ixy>
                        <ixz>0</ixz>
                        <iyz>0</iyz>
                    </inertia>
                </inertial>
                <collision name='collision'>
                    <geometry>
                        <cylinder>
                            <radius>0.11</radius>
                            <length>0.05</length>
                        </cylinder>
                    </geometry>
                    <surface>
                        <friction>
                            <ode>
                                <mu>100000</mu>
                                <mu2>100000</mu2>
                                <slip1>0</slip1>
                                <slip2>0</slip2>
                            </ode>
                            <torsional>
                                <ode/>
                            </torsional>
                        </friction>
                        <contact>
                            <ode/>
                        </contact>
                        <bounce/>
                    </surface>
                    <max_contacts>10</max_contacts>
                </collision>
                <visual name='visual'>
                    <geometry>
                        <cylinder>
                            <radius>0.11</radius>
                            <length>0.05</length>
                        </cylinder>
                    </geometry>
                    <material>
                        <script>
                            <uri>file://media/materials/scripts/gazebo.material</uri>
                            <name>Gazebo/FlatBlack</name>
                        </script>
                    </material>
                </visual>
                <self_collide>0</self_collide>
                <kinematic>0</kinematic>
            </link>
            <joint name='left_wheel_hinge' type='revolute'>
                <pose frame=''>0 0 -0.03 0 -0 0</pose>
                <child>left_wheel</child>
                <parent>chassis</parent>
                <axis>
                    <xyz>0 1 0</xyz>
                    <use_parent_model_frame>1</use_parent_model_frame>
                    <limit>
                        <lower>-1e+16</lower>
                        <upper>1e+16</upper>
                    </limit>
                    <dynamics>
                        <spring_reference>0</spring_reference>
                        <spring_stiffness>0</spring_stiffness>
                    </dynamics>
                </axis>
            </joint>
            <joint name='right_wheel_hinge' type='revolute'>
                <pose frame=''>0 0 0.03 0 -0 0</pose>
                <child>right_wheel</child>
                <parent>chassis</parent>
                <axis>
                    <xyz>0 1 0</xyz>
                    <use_parent_model_frame>1</use_parent_model_frame>
                    <limit>
                        <lower>-1e+16</lower>
                        <upper>1e+16</upper>
                    </limit>
                    <dynamics>
                        <spring_reference>0</spring_reference>
                        <spring_stiffness>0</spring_stiffness>
                    </dynamics>
                </axis>
            </joint>

            <plugin name='differential_drive_controller' filename='librobot_ros_diff_drive.so'>
                <alwaysOn>true</alwaysOn>
                <legacyMode>true</legacyMode>
                <updateRate>40</updateRate>
                <leftJoint>left_wheel_hinge</leftJoint>
                <rightJoint>right_wheel_hinge</rightJoint>
                <wheelSeparation>0.66</wheelSeparation>
                <wheelDiameter>0.26</wheelDiameter>
                <torque>5</torque>
                <commandTopic>/robot_3/cmd_vel</commandTopic>
                <odometryTopic>/robot_3/odom</odometryTopic>
                <odometryFrame>/robot_3/chassis</odometryFrame>
                <robotBaseFrame>/robot_3/odom</robotBaseFrame>
                <publishWheelTF>true</publishWheelTF>
                <publishWheelJointState>true</publishWheelJointState>
            </plugin>
        </model>

        <model name='robot_1'>
            <pose frame=''>0 0 0 0 0 0</pose>

            <link name='base'>
                <inertial>
                    <pose frame=''>0.001453 -0.000453 0.029787 0 -0 0</pose>
                    <inertia>
                        <ixx>0.05864</ixx>
                        <ixy>0.000124</ixy>
                        <ixz>0.000615</ixz>
                        <iyy>0.058786</iyy>
                        <iyz>1.4e-05</iyz>
                        <izz>1.53244</izz>
                    </inertia>
                    <mass>2.234</mass>
                </inertial>
                <collision name='base_collision'>
                    <pose frame=''>0 0 0.0478 0 -0 0</pose>
                    <geometry>
                        <cylinder>
                            <radius>0.016495</radius>
                            <length>0.061163</length>
                        </cylinder>
                    </geometry>
                    <max_contacts>10</max_contacts>
                    <surface>
                        <contact>
                            <ode/>
                        </contact>
                        <bounce/>
                        <friction>
                            <torsional>
                                <ode/>
                            </torsional>
                            <ode/>
                        </friction>
                    </surface>
                </collision>
                <visual name='base_visual'>
                    <pose frame=''>0 0 0.0478 0 -0 0</pose>
                    <geometry>
                        <mesh>
                            <uri>model://create/meshes/create_body.dae</uri>
                            <scale>1 1 1</scale>
                        </mesh>
                    </geometry>
                </visual>
                <collision name='front_wheel_collision'>
                    <pose frame=''>0.13 0 0.017 -0 1.5707 1.5707</pose>
                    <geometry>
                        <sphere>
                            <radius>0.018</radius>
                        </sphere>
                    </geometry>
                    <surface>
                        <friction>
                            <ode>
                                <mu>0</mu>
                                <mu2>0</mu2>
                                <fdir1>0 0 0</fdir1>
                                <slip1>0</slip1>
                                <slip2>0</slip2>
                            </ode>
                            <torsional>
                                <ode/>
                            </torsional>
                        </friction>
                        <contact>
                            <ode/>
                        </contact>
                        <bounce/>
                    </surface>
                    <max_contacts>10</max_contacts>
                </collision>
                <visual name='front_wheel_visual'>
                    <pose frame=''>0.13 0 0.017 -0 1.5707 1.5707</pose>
                    <geometry>
                        <sphere>
                            <radius>0.009</radius>
                        </sphere>
                    </geometry>
                </visual>
                <collision name='rear_wheel_collision'>
                    <pose frame=''>-0.13 0 0.017 -0 1.5707 1.5707</pose>
                    <geometry>
                        <sphere>
                            <radius>0.015</radius>
                        </sphere>
                    </geometry>
                    <surface>
                        <friction>
                            <ode>
                                <mu>0</mu>
                                <mu2>0</mu2>
                                <fdir1>0 0 0</fdir1>
                                <slip1>0</slip1>
                                <slip2>0</slip2>
                            </ode>
                            <torsional>
                                <ode/>
                            </torsional>
                        </friction>
                        <contact>
                            <ode/>
                        </contact>
                        <bounce/>
                    </surface>
                    <max_contacts>10</max_contacts>
                </collision>
                <visual name='rear_wheel_visual'>
                    <pose frame=''>-0.13 0 0.017 -0 1.5707 1.5707</pose>
                    <geometry>
                        <sphere>
                            <radius>0.0075</radius>
                        </sphere>
                    </geometry>
                </visual>
                <self_collide>0</self_collide>
                <kinematic>0</kinematic>
            </link>
            <link name='left_wheel'>
                <pose frame=''>0 0.13 0.032 0 -0 0</pose>
                <inertial>
                    <inertia>
                        <ixx>0.001</ixx>
                        <ixy>0</ixy>
                        <ixz>0</ixz>
                        <iyy>0.001</iyy>
                        <iyz>0</iyz>
                        <izz>0.001</izz>
                    </inertia>
                    <mass>0.01</mass>
                </inertial>
                <collision name='collision'>
                    <pose frame=''>0 0 0 -0 1.5707 1.5707</pose>
                    <geometry>
                        <cylinder>
                            <radius>0.033</radius>
                            <length>0.023</length>
                        </cylinder>
                    </geometry>
                    <surface>
                        <friction>
                            <ode>
                                <mu>10</mu>
                                <mu2>10</mu2>
                                <fdir1>0 0 0</fdir1>
                                <slip1>0</slip1>
                                <slip2>0</slip2>
                            </ode>
                            <torsional>
                                <ode/>
                            </torsional>
                        </friction>
                        <contact>
                            <ode/>
                        </contact>
                        <bounce/>
                    </surface>
                    <max_contacts>10</max_contacts>
                </collision>
                <visual name='visual'>
                    <pose frame=''>0 0 0 -0 1.5707 1.5707</pose>
                    <geometry>
                        <cylinder>
                            <radius>0.033</radius>
                            <length>0.023</length>
                        </cylinder>
                    </geometry>
                </visual>
                <self_collide>0</self_collide>
                <kinematic>0</kinematic>
            </link>
            <link name='right_wheel'>
                <pose frame=''>0 -0.13 0.032 0 -0 0</pose>
                <inertial>
                    <inertia>
                        <ixx>0.001</ixx>
                        <ixy>0</ixy>
                        <ixz>0</ixz>
                        <iyy>0.001</iyy>
                        <iyz>0</iyz>
                        <izz>0.001</izz>
                    </inertia>
                    <mass>0.01</mass>
                </inertial>
                <collision name='collision'>
                    <pose frame=''>0 0 0 -0 1.5707 1.5707</pose>
                    <geometry>
                        <cylinder>
                            <radius>0.033</radius>
                            <length>0.023</length>
                        </cylinder>
                    </geometry>
                    <surface>
                        <friction>
                            <ode>
                                <mu>10</mu>
                                <mu2>10</mu2>
                                <fdir1>0 0 0</fdir1>
                                <slip1>0</slip1>
                                <slip2>0</slip2>
                            </ode>
                            <torsional>
                                <ode/>
                            </torsional>
                        </friction>
                        <contact>
                            <ode/>
                        </contact>
                        <bounce/>
                    </surface>
                    <max_contacts>10</max_contacts>
                </collision>
                <visual name='visual'>
                    <pose frame=''>0 0 0 -0 1.5707 1.5707</pose>
                    <geometry>
                        <cylinder>
                            <radius>0.033</radius>
                            <length>0.023</length>
                        </cylinder>
                    </geometry>
                </visual>
                <self_collide>0</self_collide>
                <kinematic>0</kinematic>
            </link>
            <joint name='left_wheel' type='revolute'>
                <parent>base</parent>
                <child>left_wheel</child>
                <axis>
                    <xyz>0 1 0</xyz>
                    <use_parent_model_frame>1</use_parent_model_frame>
                    <limit>
                        <lower>-1e+16</lower>
                        <upper>1e+16</upper>
                    </limit>
                    <dynamics>
                        <spring_reference>0</spring_reference>
                        <spring_stiffness>0</spring_stiffness>
                    </dynamics>
                </axis>
            </joint>
            <joint name='right_wheel' type='revolute'>
                <parent>base</parent>
                <child>right_wheel</child>
                <axis>
                    <xyz>0 1 0</xyz>
                    <use_parent_model_frame>1</use_parent_model_frame>
                    <limit>
                        <lower>-1e+16</lower>
                        <upper>1e+16</upper>
                    </limit>
                    <dynamics>
                        <spring_reference>0</spring_reference>
                        <spring_stiffness>0</spring_stiffness>
                    </dynamics>
                </axis>
            </joint>

            <plugin name='differential_drive_controller' filename='librobot_ros_diff_drive.so'>
                <alwaysOn>true</alwaysOn>
                <legacyMode>true</legacyMode>
                <updateRate>40</updateRate>
                <leftJoint>left_wheel</leftJoint>
                <rightJoint>right_wheel</rightJoint>
                <wheelSeparation>0.66</wheelSeparation>
                <wheelDiameter>0.26</wheelDiameter>
                <torque>5</torque>
                <commandTopic>/robot_1/cmd_vel</commandTopic>
                <odometryTopic>/robot_1/odom</odometryTopic>
                <odometryFrame>/robot_1/chassis</odometryFrame>
                <robotBaseFrame>/robot_1/odom</robotBaseFrame>
                <publishWheelTF>true</publishWheelTF>
                <publishWheelJointState>true</publishWheelJointState>
            </plugin>
        </model>

        <model name='robot_4'>
            <pose frame=''>3 3 0 0 0 0</pose>
            <link name='base_footprint'>
                <pose frame=''>0 0 0 0 -0 0</pose>
                <inertial>
                    <pose frame=''>0 0 -0.05 0 -0 0</pose>
                    <inertia>
                        <ixx>1</ixx>
                        <ixy>0</ixy>
                        <ixz>0</ixz>
                        <iyy>1</iyy>
                        <iyz>0</iyz>
                        <izz>1</izz>
                    </inertia>
                    <mass>0.1</mass>
                </inertial>
                <collision name='base_footprint_geom'>
                    <pose frame=''>0 0 -0.05 0 -0 0</pose>
                    <geometry>
                        <box>
                            <size>0.001 0.001 0.001</size>
                        </box>
                    </geometry>
                    <surface>
                        <friction>
                            <ode>
                                <mu>0</mu>
                                <mu2>0</mu2>
                                <fdir1>0 0 0</fdir1>
                                <slip1>0</slip1>
                                <slip2>0</slip2>
                            </ode>
                            <torsional>
                                <ode/>
                            </torsional>
                        </friction>
                        <bounce>
                            <restitution_coefficient>0</restitution_coefficient>
                            <threshold>0</threshold>
                        </bounce>
                        <contact>
                            <ode>
                                <soft_cfm>0</soft_cfm>
                                <soft_erp>0.2</soft_erp>
                                <kp>1e+13</kp>
                                <kd>1e+11</kd>
                                <max_vel>-1</max_vel>
                                <min_depth>0</min_depth>
                            </ode>
                        </contact>
                    </surface>
                    <laser_retro>0</laser_retro>
                    <max_contacts>10</max_contacts>
                </collision>
                <visual name='base_footprint_geom_visual'>
                    <pose frame=''>0 0 0 0 -0 0</pose>
                    <geometry>
                        <box>
                            <size>0.001 0.001 0.001</size>
                        </box>
                    </geometry>
                </visual>
                <gravity>1</gravity>
                <self_collide>0</self_collide>
                <kinematic>0</kinematic>
            </link>
            <link name='base_link'>
                <pose frame=''>0 0 0 0 -0 0</pose>
                <inertial>
                    <pose frame=''>0 0 0 0 -0 0</pose>
                    <inertia>
                        <ixx>5.65223</ixx>
                        <ixy>-0.00972</ixy>
                        <ixz>1.29399</ixz>
                        <iyy>5.66947</iyy>
                        <iyz>-0.00738</iyz>
                        <izz>3.6832</izz>
                    </inertia>
                    <mass>22</mass>
                </inertial>
                <collision name='base_link_geom'>
                    <pose frame=''>0 0 0 0 -0 0</pose>
                    <geometry>
                        <mesh>
                            <uri>model://youbot/meshes/base/base_convex.stl</uri>
                            <scale>1 1 1</scale>
                        </mesh>
                    </geometry>
                    <surface>
                        <friction>
                            <ode>
                                <mu>0</mu>
                                <mu2>0</mu2>
                                <fdir1>0 0 0</fdir1>
                                <slip1>0</slip1>
                                <slip2>0</slip2>
                            </ode>
                            <torsional>
                                <ode/>
                            </torsional>
                        </friction>
                        <bounce>
                            <restitution_coefficient>0</restitution_coefficient>
                            <threshold>0</threshold>
                        </bounce>
                        <contact>
                            <ode>
                                <soft_cfm>0</soft_cfm>
                                <soft_erp>0.2</soft_erp>
                                <kp>1e+13</kp>
                                <kd>1e+11</kd>
                                <max_vel>-1</max_vel>
                                <min_depth>0</min_depth>
                            </ode>
                        </contact>
                    </surface>
                    <laser_retro>0</laser_retro>
                    <max_contacts>10</max_contacts>
                </collision>
                <visual name='base_link_geom_visual'>
                    <pose frame=''>0 0 0 0 -0 0</pose>
                    <geometry>
                        <mesh>
                            <uri>model://youbot/meshes/base/base.dae</uri>
                            <scale>1 1 1</scale>
                        </mesh>
                    </geometry>
                </visual>
                <gravity>1</gravity>
                <self_collide>0</self_collide>
                <kinematic>0</kinematic>
            </link>

            <link name='base_laser_front_link'>
                <pose frame=''>0.3 0 -0.03 0 -0 0</pose>
                <inertial>
                    <pose frame=''>0 0 0 0 -0 0</pose>
                    <inertia>
                        <ixx>0.1</ixx>
                        <ixy>0</ixy>
                        <ixz>0</ixz>
                        <iyy>0.1</iyy>
                        <iyz>0</iyz>
                        <izz>0.1</izz>
                    </inertia>
                    <mass>0.16</mass>
                </inertial>
                <collision name='base_laser_front_link_geom'>
                    <pose frame=''>0 0 0 0 -0 0</pose>
                    <geometry>
                        <mesh>
                            <uri>model://hokuyo/meshes/hokuyo_convex.stl</uri>
                            <scale>1 1 1</scale>
                        </mesh>
                    </geometry>
                    <surface>
                        <bounce>
                            <restitution_coefficient>0</restitution_coefficient>
                            <threshold>0</threshold>
                        </bounce>
                        <contact>
                            <ode>
                                <soft_cfm>0</soft_cfm>
                                <soft_erp>0.2</soft_erp>
                                <kp>1e+13</kp>
                                <kd>1e+11</kd>
                                <max_vel>-1</max_vel>
                                <min_depth>0</min_depth>
                            </ode>
                        </contact>
                        <friction>
                            <torsional>
                                <ode/>
                            </torsional>
                            <ode/>
                        </friction>
                    </surface>
                    <laser_retro>0</laser_retro>
                    <max_contacts>10</max_contacts>
                </collision>
                <visual name='base_laser_front_link_geom_visual'>
                    <pose frame=''>0 0 0 0 -0 0</pose>
                    <geometry>
                        <mesh>
                            <uri>model://hokuyo/meshes/hokuyo.dae</uri>
                            <scale>1 1 1</scale>
                        </mesh>
                    </geometry>
                </visual>
                <sensor name='base_laser_front' type='ray'>
                    <pose frame=''>0 0 0 0 -0 0</pose>
                    <ray>
                        <scan>
                            <horizontal>
                                <samples>640</samples>
                                <resolution>1</resolution>
                                <min_angle>-1.57</min_angle>
                                <max_angle>1.57</max_angle>
                            </horizontal>
                            <vertical>
                                <samples>1</samples>
                                <min_angle>0</min_angle>
                                <max_angle>0</max_angle>
                            </vertical>
                        </scan>
                        <range>
                            <min>0.05</min>
                            <max>5.6</max>
                            <resolution>0.36</resolution>
                        </range>
                    </ray>
                    <always_on>0</always_on>
                    <update_rate>10</update_rate>
                    <visualize>0</visualize>
                </sensor>
                <gravity>1</gravity>
                <self_collide>0</self_collide>
                <kinematic>0</kinematic>
            </link>
            <link name='caster_link_bl'>
                <pose frame=''>-0.228 0.158 -0.034 0 -0 0</pose>
                <inertial>
                    <pose frame=''>0 0 0 0 -0 0</pose>
                    <inertia>
                        <ixx>0.012412</ixx>
                        <ixy>-0.000712</ixy>
                        <ixz>0.000503</ixz>
                        <iyy>0.015218</iyy>
                        <iyz>-4e-06</iyz>
                        <izz>0.011764</izz>
                    </inertia>
                    <mass>0.1</mass>
                </inertial>
                <gravity>1</gravity>
                <self_collide>0</self_collide>
                <kinematic>0</kinematic>
            </link>
            <link name='wheel_link_bl'>
                <pose frame=''>-0.228 0.158 -0.034 0 -0 0</pose>
                <inertial>
                    <pose frame=''>0 0 0 0 -0 0</pose>
                    <inertia>
                        <ixx>0.012412</ixx>
                        <ixy>-0.000712</ixy>
                        <ixz>0.000503</ixz>
                        <iyy>0.015218</iyy>
                        <iyz>-4e-06</iyz>
                        <izz>0.011764</izz>
                    </inertia>
                    <mass>0.4</mass>
                </inertial>
                <collision name='wheel_link_bl_geom'>
                    <pose frame=''>0 0 0 1.5708 -0 0</pose>
                    <geometry>
                        <cylinder>
                            <radius>0.05</radius>
                            <length>0.005</length>
                        </cylinder>
                    </geometry>
                    <surface>
                        <bounce>
                            <restitution_coefficient>0</restitution_coefficient>
                            <threshold>0</threshold>
                        </bounce>
                        <contact>
                            <ode>
                                <soft_cfm>0</soft_cfm>
                                <soft_erp>0.2</soft_erp>
                                <kp>1e+13</kp>
                                <kd>1e+11</kd>
                                <max_vel>-1</max_vel>
                                <min_depth>0</min_depth>
                            </ode>
                        </contact>
                        <friction>
                            <torsional>
                                <ode/>
                            </torsional>
                            <ode/>
                        </friction>
                    </surface>
                    <laser_retro>0</laser_retro>
                    <max_contacts>10</max_contacts>
                </collision>
                <visual name='wheel_link_bl_geom_visual'>
                    <pose frame=''>0 0 0 0 -0 0</pose>
                    <geometry>
                        <mesh>
                            <uri>model://youbot/meshes/base/back-left_wheel.dae</uri>
                            <scale>1 1 1</scale>
                        </mesh>
                    </geometry>
                    <material>
                        <script>
                            <uri>model://youbot/materials/scripts/youbot.material</uri>
                            <name>youbot/Orange</name>
                        </script>
                    </material>
                </visual>
                <gravity>1</gravity>
                <self_collide>0</self_collide>
                <kinematic>0</kinematic>
            </link>
            <link name='caster_link_br'>
                <pose frame=''>-0.228 -0.158 -0.034 0 -0 0</pose>
                <inertial>
                    <pose frame=''>0 0 0 0 -0 0</pose>
                    <inertia>
                        <ixx>0.012412</ixx>
                        <ixy>-0.000712</ixy>
                        <ixz>0.000503</ixz>
                        <iyy>0.015218</iyy>
                        <iyz>-4e-06</iyz>
                        <izz>0.011764</izz>
                    </inertia>
                    <mass>0.1</mass>
                </inertial>
                <gravity>1</gravity>
                <self_collide>0</self_collide>
                <kinematic>0</kinematic>
            </link>
            <link name='wheel_link_br'>
                <pose frame=''>-0.228 -0.158 -0.034 0 -0 0</pose>
                <inertial>
                    <pose frame=''>0 0 0 0 -0 0</pose>
                    <inertia>
                        <ixx>0.012412</ixx>
                        <ixy>-0.000712</ixy>
                        <ixz>0.000503</ixz>
                        <iyy>0.015218</iyy>
                        <iyz>-4e-06</iyz>
                        <izz>0.011764</izz>
                    </inertia>
                    <mass>0.4</mass>
                </inertial>
                <collision name='wheel_link_br_geom'>
                    <pose frame=''>0 0 0 1.5708 -0 0</pose>
                    <geometry>
                        <cylinder>
                            <radius>0.05</radius>
                            <length>0.005</length>
                        </cylinder>
                    </geometry>
                    <surface>
                        <bounce>
                            <restitution_coefficient>0</restitution_coefficient>
                            <threshold>0</threshold>
                        </bounce>
                        <contact>
                            <ode>
                                <soft_cfm>0</soft_cfm>
                                <soft_erp>0.2</soft_erp>
                                <kp>1e+13</kp>
                                <kd>1e+11</kd>
                                <max_vel>-1</max_vel>
                                <min_depth>0</min_depth>
                            </ode>
                        </contact>
                        <friction>
                            <torsional>
                                <ode/>
                            </torsional>
                            <ode/>
                        </friction>
                    </surface>
                    <laser_retro>0</laser_retro>
                    <max_contacts>10</max_contacts>
                </collision>
                <visual name='wheel_link_br_geom_visual'>
                    <pose frame=''>0 0 0 0 -0 0</pose>
                    <geometry>
                        <mesh>
                            <uri>model://youbot/meshes/base/back-right_wheel.dae</uri>
                            <scale>1 1 1</scale>
                        </mesh>
                    </geometry>
                    <material>
                        <script>
                            <uri>model://youbot/materials/scripts/youbot.material</uri>
                            <name>youbot/Orange</name>
                        </script>
                    </material>
                </visual>
                <gravity>1</gravity>
                <self_collide>0</self_collide>
                <kinematic>0</kinematic>
            </link>
            <link name='caster_link_fl'>
                <pose frame=''>0.228 0.158 -0.034 0 -0 0</pose>
                <inertial>
                    <pose frame=''>0 0 0 0 -0 0</pose>
                    <inertia>
                        <ixx>0.012412</ixx>
                        <ixy>-0.000712</ixy>
                        <ixz>0.000503</ixz>
                        <iyy>0.015218</iyy>
                        <iyz>-4e-06</iyz>
                        <izz>0.011764</izz>
                    </inertia>
                    <mass>0.1</mass>
                </inertial>
                <gravity>1</gravity>
                <self_collide>0</self_collide>
                <kinematic>0</kinematic>
            </link>
            <link name='wheel_link_fl'>
                <pose frame=''>0.228 0.158 -0.034 0 -0 0</pose>
                <inertial>
                    <pose frame=''>0 0 0 0 -0 0</pose>
                    <inertia>
                        <ixx>0.012412</ixx>
                        <ixy>-0.000712</ixy>
                        <ixz>0.000503</ixz>
                        <iyy>0.015218</iyy>
                        <iyz>-4e-06</iyz>
                        <izz>0.011764</izz>
                    </inertia>
                    <mass>0.4</mass>
                </inertial>
                <collision name='wheel_link_fl_geom'>
                    <pose frame=''>0 0 0 1.5708 -0 0</pose>
                    <geometry>
                        <cylinder>
                            <radius>0.05</radius>
                            <length>0.005</length>
                        </cylinder>
                    </geometry>
                    <surface>
                        <bounce>
                            <restitution_coefficient>0</restitution_coefficient>
                            <threshold>0</threshold>
                        </bounce>
                        <contact>
                            <ode>
                                <soft_cfm>0</soft_cfm>
                                <soft_erp>0.2</soft_erp>
                                <kp>1e+13</kp>
                                <kd>1e+11</kd>
                                <max_vel>-1</max_vel>
                                <min_depth>0</min_depth>
                            </ode>
                        </contact>
                        <friction>
                            <torsional>
                                <ode/>
                            </torsional>
                            <ode/>
                        </friction>
                    </surface>
                    <laser_retro>0</laser_retro>
                    <max_contacts>10</max_contacts>
                </collision>
                <visual name='wheel_link_fl_geom_visual'>
                    <pose frame=''>0 0 0 0 -0 0</pose>
                    <geometry>
                        <mesh>
                            <uri>model://youbot/meshes/base/front-left_wheel.dae</uri>
                            <scale>1 1 1</scale>
                        </mesh>
                    </geometry>
                    <material>
                        <script>
                            <uri>model://youbot/materials/scripts/youbot.material</uri>
                            <name>youbot/Orange</name>
                        </script>
                    </material>
                </visual>
                <gravity>1</gravity>
                <self_collide>0</self_collide>
                <kinematic>0</kinematic>
            </link>
            <link name='caster_link_fr'>
                <pose frame=''>0.228 -0.158 -0.034 0 -0 0</pose>
                <inertial>
                    <pose frame=''>0 0 0 0 -0 0</pose>
                    <inertia>
                        <ixx>0.012412</ixx>
                        <ixy>-0.000712</ixy>
                        <ixz>0.000503</ixz>
                        <iyy>0.015218</iyy>
                        <iyz>-4e-06</iyz>
                        <izz>0.011764</izz>
                    </inertia>
                    <mass>0.1</mass>
                </inertial>
                <gravity>1</gravity>
                <self_collide>0</self_collide>
                <kinematic>0</kinematic>
            </link>
            <link name='wheel_link_fr'>
                <pose frame=''>0.228 -0.158 -0.034 0 -0 0</pose>
                <inertial>
                    <pose frame=''>0 0 0 0 -0 0</pose>
                    <inertia>
                        <ixx>0.012412</ixx>
                        <ixy>-0.000712</ixy>
                        <ixz>0.000503</ixz>
                        <iyy>0.015218</iyy>
                        <iyz>-4e-06</iyz>
                        <izz>0.011764</izz>
                    </inertia>
                    <mass>0.4</mass>
                </inertial>
                <collision name='wheel_link_fr_geom'>
                    <pose frame=''>0 0 0 1.5708 -0 0</pose>
                    <geometry>
                        <cylinder>
                            <radius>0.05</radius>
                            <length>0.005</length>
                        </cylinder>
                    </geometry>
                    <surface>
                        <bounce>
                            <restitution_coefficient>0</restitution_coefficient>
                            <threshold>0</threshold>
                        </bounce>
                        <contact>
                            <ode>
                                <soft_cfm>0</soft_cfm>
                                <soft_erp>0.2</soft_erp>
                                <kp>1e+13</kp>
                                <kd>1e+11</kd>
                                <max_vel>-1</max_vel>
                                <min_depth>0</min_depth>
                            </ode>
                        </contact>
                        <friction>
                            <torsional>
                                <ode/>
                            </torsional>
                            <ode/>
                        </friction>
                    </surface>
                    <laser_retro>0</laser_retro>
                    <max_contacts>10</max_contacts>
                </collision>
                <visual name='wheel_link_fr_geom_visual'>
                    <pose frame=''>0 0 0 0 -0 0</pose>
                    <geometry>
                        <mesh>
                            <uri>model://youbot/meshes/base/front-right_wheel.dae</uri>
                            <scale>1 1 1</scale>
                        </mesh>
                    </geometry>
                    <material>
                        <script>
                            <uri>model://youbot/materials/scripts/youbot.material</uri>
                            <name>youbot/Orange</name>
                        </script>
                    </material>
                </visual>
                <gravity>1</gravity>
                <self_collide>0</self_collide>
                <kinematic>0</kinematic>
            </link>

            <joint name='base_footprint_joint' type='revolute'>
                <pose frame=''>0 0 0 0 -0 0</pose>
                <parent>base_footprint</parent>
                <child>base_link</child>
                <axis>
                    <dynamics>
                        <damping>0</damping>
                        <friction>0</friction>
                        <spring_reference>0</spring_reference>
                        <spring_stiffness>0</spring_stiffness>
                    </dynamics>
                    <limit>
                        <lower>0</lower>
                        <upper>0</upper>
                        <effort>0</effort>
                        <velocity>0</velocity>
                    </limit>
                    <xyz>0 0 1</xyz>
                    <use_parent_model_frame>1</use_parent_model_frame>
                </axis>
            </joint>
            <joint name='base_laser_front_hokuyo_urg04_laser_joint' type='revolute'>
                <pose frame=''>0 0 0 0 -0 0</pose>
                <parent>base_link</parent>
                <child>base_laser_front_link</child>
                <axis>
                    <dynamics>
                        <damping>0</damping>
                        <friction>0</friction>
                        <spring_reference>0</spring_reference>
                        <spring_stiffness>0</spring_stiffness>
                    </dynamics>
                    <limit>
                        <lower>0</lower>
                        <upper>0</upper>
                        <effort>0</effort>
                        <velocity>0</velocity>
                    </limit>
                    <xyz>0 0 1</xyz>
                    <use_parent_model_frame>1</use_parent_model_frame>
                </axis>
            </joint>
            <joint name='caster_joint_bl' type='revolute'>
                <pose frame=''>0 0 0 0 -0 0</pose>
                <parent>base_link</parent>
                <child>caster_link_bl</child>
                <axis>
                    <dynamics>
                        <damping>1</damping>
                        <friction>0</friction>
                        <spring_reference>0</spring_reference>
                        <spring_stiffness>0</spring_stiffness>
                    </dynamics>
                    <limit>
                        <effort>1</effort>
                        <lower>-1e+16</lower>
                        <upper>1e+16</upper>
                    </limit>
                    <xyz>0 0 1</xyz>
                    <use_parent_model_frame>1</use_parent_model_frame>
                </axis>
            </joint>
            <joint name='wheel_joint_bl' type='revolute'>
                <pose frame=''>0 0 0 0 -0 0</pose>
                <parent>caster_link_bl</parent>
                <child>wheel_link_bl</child>
                <axis>
                    <dynamics>
                        <damping>1</damping>
                        <friction>0</friction>
                        <spring_reference>0</spring_reference>
                        <spring_stiffness>0</spring_stiffness>
                    </dynamics>
                    <limit>
                        <effort>1</effort>
                        <lower>-1e+16</lower>
                        <upper>1e+16</upper>
                    </limit>
                    <xyz>0 1 0</xyz>
                    <use_parent_model_frame>1</use_parent_model_frame>
                </axis>
            </joint>
            <joint name='caster_joint_br' type='revolute'>
                <pose frame=''>0 0 0 0 -0 0</pose>
                <parent>base_link</parent>
                <child>caster_link_br</child>
                <axis>
                    <dynamics>
                        <damping>1</damping>
                        <friction>0</friction>
                        <spring_reference>0</spring_reference>
                        <spring_stiffness>0</spring_stiffness>
                    </dynamics>
                    <limit>
                        <effort>1</effort>
                        <lower>-1e+16</lower>
                        <upper>1e+16</upper>
                    </limit>
                    <xyz>0 0 1</xyz>
                    <use_parent_model_frame>1</use_parent_model_frame>
                </axis>
            </joint>
            <joint name='wheel_joint_br' type='revolute'>
                <pose frame=''>0 0 0 0 -0 0</pose>
                <parent>caster_link_br</parent>
                <child>wheel_link_br</child>
                <axis>
                    <dynamics>
                        <damping>1</damping>
                        <friction>0</friction>
                        <spring_reference>0</spring_reference>
                        <spring_stiffness>0</spring_stiffness>
                    </dynamics>
                    <limit>
                        <effort>1</effort>
                        <lower>-1e+16</lower>
                        <upper>1e+16</upper>
                    </limit>
                    <xyz>0 1 0</xyz>
                    <use_parent_model_frame>1</use_parent_model_frame>
                </axis>
            </joint>
            <joint name='caster_joint_fl' type='revolute'>
                <pose frame=''>0 0 0 0 -0 0</pose>
                <parent>base_link</parent>
                <child>caster_link_fl</child>
                <axis>
                    <dynamics>
                        <damping>1</damping>
                        <friction>0</friction>
                        <spring_reference>0</spring_reference>
                        <spring_stiffness>0</spring_stiffness>
                    </dynamics>
                    <limit>
                        <effort>1</effort>
                        <lower>-1e+16</lower>
                        <upper>1e+16</upper>
                    </limit>
                    <xyz>0 0 1</xyz>
                    <use_parent_model_frame>1</use_parent_model_frame>
                </axis>
            </joint>
            <joint name='wheel_joint_fl' type='revolute'>
                <pose frame=''>0 0 0 0 -0 0</pose>
                <parent>caster_link_fl</parent>
                <child>wheel_link_fl</child>
                <axis>
                    <dynamics>
                        <damping>1</damping>
                        <friction>0</friction>
                        <spring_reference>0</spring_reference>
                        <spring_stiffness>0</spring_stiffness>
                    </dynamics>
                    <limit>
                        <effort>1</effort>
                        <lower>-1e+16</lower>
                        <upper>1e+16</upper>
                    </limit>
                    <xyz>0 1 0</xyz>
                    <use_parent_model_frame>1</use_parent_model_frame>
                </axis>
            </joint>
            <joint name='caster_joint_fr' type='revolute'>
                <pose frame=''>0 0 0 0 -0 0</pose>
                <parent>base_link</parent>
                <child>caster_link_fr</child>
                <axis>
                    <dynamics>
                        <damping>1</damping>
                        <friction>0</friction>
                        <spring_reference>0</spring_reference>
                        <spring_stiffness>0</spring_stiffness>
                    </dynamics>
                    <limit>
                        <effort>1</effort>
                        <lower>-1e+16</lower>
                        <upper>1e+16</upper>
                    </limit>
                    <xyz>0 0 1</xyz>
                    <use_parent_model_frame>1</use_parent_model_frame>
                </axis>
            </joint>
            <joint name='wheel_joint_fr' type='revolute'>
                <pose frame=''>0 0 0 0 -0 0</pose>
                <parent>caster_link_fr</parent>
                <child>wheel_link_fr</child>
                <axis>
                    <dynamics>
                        <damping>1</damping>
                        <friction>0</friction>
                        <spring_reference>0</spring_reference>
                        <spring_stiffness>0</spring_stiffness>
                    </dynamics>
                    <limit>
                        <effort>1</effort>
                        <lower>-1e+16</lower>
                        <upper>1e+16</upper>
                    </limit>
                    <xyz>0 1 0</xyz>
                    <use_parent_model_frame>1</use_parent_model_frame>
                </axis>
            </joint>

            <static>0</static>

            <plugin name='differential_drive_controller' filename='librobot_ros_diff_drive.so'>
                <alwaysOn>true</alwaysOn>
                <legacyMode>true</legacyMode>
                <updateRate>40</updateRate>
                <leftJoint>wheel_joint_br</leftJoint>
                <rightJoint>wheel_joint_bl</rightJoint>
                <wheelSeparation>0.66</wheelSeparation>
                <wheelDiameter>0.26</wheelDiameter>
                <torque>5</torque>
                <commandTopic>/robot_4/cmd_vel</commandTopic>
                <odometryTopic>/robot_4/odom</odometryTopic>
                <odometryFrame>/robot_4/chassis</odometryFrame>
                <robotBaseFrame>/robot_4/odom</robotBaseFrame>
                <publishWheelTF>true</publishWheelTF>
                <publishWheelJointState>true</publishWheelJointState>
            </plugin>
        </model>

    </world>
</sdf>
